// console.lag("a");

console.log("after the error!");

try{
    // throw new Error("Throwing an error from try block!");
    console.lag(x);
    // console.log("Hello!");
}
catch(error){
    console.log(error);
}
finally{
    console.log("This is finnaly block!");
}

console.log("after try catch!");